<?xml version="1.0" ?>
<robot name="frame" xmlns:xacro="http://www.ros.org/wiki/xacro">

<xacro:include filename="$(find frame_description)/urdf/materials.xacro" />
<xacro:include filename="$(find frame_description)/urdf/frame.ros2control" />
<xacro:include filename="$(find frame_description)/urdf/frame.gazebo" />
<link name="base_link">
  <inertial>
    <origin xyz="5.361940941515797e-15 -0.006931498212032427 1.0942736615338362e-16" rpy="0 0 0"/>
    <mass value="0.950824254848482"/>
    <inertia ixx="0.010991" iyy="0.017094" izz="0.010991" ixy="0.0" iyz="0.0" ixz="0.0"/>
  </inertial>
  <visual>
    <origin xyz="0 0 0" rpy="0 0 0"/>
    <geometry>
      <mesh filename="file://$(find frame_description)/meshes/base_link.stl" scale="0.001 0.001 0.001"/>
    </geometry>
    <material name="silver"/>
  </visual>
  <collision>
    <origin xyz="0 0 0" rpy="0 0 0"/>
    <geometry>
      <mesh filename="file://$(find frame_description)/meshes/base_link.stl" scale="0.001 0.001 0.001"/>
    </geometry>
  </collision>
</link>

<link name="arm_7_1">
  <inertial>
    <origin xyz="-0.08302889455495802 -2.527437287236367e-11 -0.0973299825380552" rpy="0 0 0"/>
    <mass value="0.15422742956922936"/>
    <inertia ixx="0.000389" iyy="0.000929" izz="0.0006" ixy="-0.0" iyz="-0.0" ixz="-0.000277"/>
  </inertial>
  <visual>
    <origin xyz="0.055 -0.02 0.2" rpy="0 0 0"/>
    <geometry>
      <mesh filename="file://$(find frame_description)/meshes/arm_7_1.stl" scale="0.001 0.001 0.001"/>
    </geometry>
    <material name="silver"/>
  </visual>
  <collision>
    <origin xyz="0.055 -0.02 0.2" rpy="0 0 0"/>
    <geometry>
      <mesh filename="file://$(find frame_description)/meshes/arm_7_1.stl" scale="0.001 0.001 0.001"/>
    </geometry>
  </collision>
</link>

<link name="arm_8_1">
  <inertial>
    <origin xyz="-0.0973299825380552 2.527436940291672e-11 -0.08302889455495804" rpy="0 0 0"/>
    <mass value="0.15422742956922936"/>
    <inertia ixx="0.0006" iyy="0.000929" izz="0.000389" ixy="0.0" iyz="0.0" ixz="-0.000277"/>
  </inertial>
  <visual>
    <origin xyz="0.2 -0.02 0.055" rpy="0 0 0"/>
    <geometry>
      <mesh filename="file://$(find frame_description)/meshes/arm_8_1.stl" scale="0.001 0.001 0.001"/>
    </geometry>
    <material name="silver"/>
  </visual>
  <collision>
    <origin xyz="0.2 -0.02 0.055" rpy="0 0 0"/>
    <geometry>
      <mesh filename="file://$(find frame_description)/meshes/arm_8_1.stl" scale="0.001 0.001 0.001"/>
    </geometry>
  </collision>
</link>

<link name="arm_6_1">
  <inertial>
    <origin xyz="0.0973299825380552 2.5274376341810623e-11 0.08302889455495804" rpy="0 0 0"/>
    <mass value="0.15422742956922936"/>
    <inertia ixx="0.0006" iyy="0.000929" izz="0.000389" ixy="-0.0" iyz="-0.0" ixz="-0.000277"/>
  </inertial>
  <visual>
    <origin xyz="-0.2 -0.02 -0.055" rpy="0 0 0"/>
    <geometry>
      <mesh filename="file://$(find frame_description)/meshes/arm_6_1.stl" scale="0.001 0.001 0.001"/>
    </geometry>
    <material name="silver"/>
  </visual>
  <collision>
    <origin xyz="-0.2 -0.02 -0.055" rpy="0 0 0"/>
    <geometry>
      <mesh filename="file://$(find frame_description)/meshes/arm_6_1.stl" scale="0.001 0.001 0.001"/>
    </geometry>
  </collision>
</link>

<link name="arm_5_1">
  <inertial>
    <origin xyz="0.08302889455495802 -2.527437287236367e-11 0.0973299825380552" rpy="0 0 0"/>
    <mass value="0.15422742956922936"/>
    <inertia ixx="0.000389" iyy="0.000929" izz="0.0006" ixy="0.0" iyz="0.0" ixz="-0.000277"/>
  </inertial>
  <visual>
    <origin xyz="-0.055 -0.02 -0.2" rpy="0 0 0"/>
    <geometry>
      <mesh filename="file://$(find frame_description)/meshes/arm_5_1.stl" scale="0.001 0.001 0.001"/>
    </geometry>
    <material name="silver"/>
  </visual>
  <collision>
    <origin xyz="-0.055 -0.02 -0.2" rpy="0 0 0"/>
    <geometry>
      <mesh filename="file://$(find frame_description)/meshes/arm_5_1.stl" scale="0.001 0.001 0.001"/>
    </geometry>
  </collision>
</link>

<link name="arm_4_1">
  <inertial>
    <origin xyz="0.0973299825380552 -2.527437287236367e-11 -0.08302889455495804" rpy="0 0 0"/>
    <mass value="0.15422742956922936"/>
    <inertia ixx="0.0006" iyy="0.000929" izz="0.000389" ixy="0.0" iyz="-0.0" ixz="0.000277"/>
  </inertial>
  <visual>
    <origin xyz="-0.2 -0.02 0.055" rpy="0 0 0"/>
    <geometry>
      <mesh filename="file://$(find frame_description)/meshes/arm_4_1.stl" scale="0.001 0.001 0.001"/>
    </geometry>
    <material name="silver"/>
  </visual>
  <collision>
    <origin xyz="-0.2 -0.02 0.055" rpy="0 0 0"/>
    <geometry>
      <mesh filename="file://$(find frame_description)/meshes/arm_4_1.stl" scale="0.001 0.001 0.001"/>
    </geometry>
  </collision>
</link>

<link name="arm_3_1">
  <inertial>
    <origin xyz="0.08302889455495802 2.527436940291672e-11 -0.0973299825380552" rpy="0 0 0"/>
    <mass value="0.15422742956922936"/>
    <inertia ixx="0.000389" iyy="0.000929" izz="0.0006" ixy="-0.0" iyz="0.0" ixz="0.000277"/>
  </inertial>
  <visual>
    <origin xyz="-0.055 -0.02 0.2" rpy="0 0 0"/>
    <geometry>
      <mesh filename="file://$(find frame_description)/meshes/arm_3_1.stl" scale="0.001 0.001 0.001"/>
    </geometry>
    <material name="silver"/>
  </visual>
  <collision>
    <origin xyz="-0.055 -0.02 0.2" rpy="0 0 0"/>
    <geometry>
      <mesh filename="file://$(find frame_description)/meshes/arm_3_1.stl" scale="0.001 0.001 0.001"/>
    </geometry>
  </collision>
</link>

<link name="arm_2_1">
  <inertial>
    <origin xyz="-0.09732998253804703 -2.5274383280704527e-11 0.08302889455496792" rpy="0 0 0"/>
    <mass value="0.15422742956922936"/>
    <inertia ixx="0.0006" iyy="0.000929" izz="0.000389" ixy="-0.0" iyz="0.0" ixz="0.000277"/>
  </inertial>
  <visual>
    <origin xyz="0.2 -0.02 -0.055" rpy="0 0 0"/>
    <geometry>
      <mesh filename="file://$(find frame_description)/meshes/arm_2_1.stl" scale="0.001 0.001 0.001"/>
    </geometry>
    <material name="silver"/>
  </visual>
  <collision>
    <origin xyz="0.2 -0.02 -0.055" rpy="0 0 0"/>
    <geometry>
      <mesh filename="file://$(find frame_description)/meshes/arm_2_1.stl" scale="0.001 0.001 0.001"/>
    </geometry>
  </collision>
</link>

<link name="arm_1_1">
  <inertial>
    <origin xyz="-0.08302889455495796 2.5278522330918207e-11 0.09732998253805508" rpy="0 0 0"/>
    <mass value="0.15422742956922936"/>
    <inertia ixx="0.000389" iyy="0.000929" izz="0.0006" ixy="0.0" iyz="-0.0" ixz="0.000277"/>
  </inertial>
  <visual>
    <origin xyz="0.055 -0.02 -0.2" rpy="0 0 0"/>
    <geometry>
      <mesh filename="file://$(find frame_description)/meshes/arm_1_1.stl" scale="0.001 0.001 0.001"/>
    </geometry>
    <material name="silver"/>
  </visual>
  <collision>
    <origin xyz="0.055 -0.02 -0.2" rpy="0 0 0"/>
    <geometry>
      <mesh filename="file://$(find frame_description)/meshes/arm_1_1.stl" scale="0.001 0.001 0.001"/>
    </geometry>
  </collision>
</link>

<link name="holder_4_1">
  <inertial>
    <origin xyz="0.0012743502456399602 -1.933707013956898e-11 -0.016274350245639946" rpy="0 0 0"/>
    <mass value="0.545696208866394"/>
    <inertia ixx="0.00016" iyy="0.000161" izz="0.00016" ixy="-0.0" iyz="0.0" ixz="-1e-06"/>
  </inertial>
  <visual>
    <origin xyz="0.2 -0.02 -0.215" rpy="0 0 0"/>
    <geometry>
      <mesh filename="file://$(find frame_description)/meshes/holder_4_1.stl" scale="0.001 0.001 0.001"/>
    </geometry>
    <material name="silver"/>
  </visual>
  <collision>
    <origin xyz="0.2 -0.02 -0.215" rpy="0 0 0"/>
    <geometry>
      <mesh filename="file://$(find frame_description)/meshes/holder_4_1.stl" scale="0.001 0.001 0.001"/>
    </geometry>
  </collision>
</link>

<link name="holder_4_1">
  <inertial>
    <origin xyz="0.016274350245639946 -1.933707013956898e-11 -0.0012743502456399602" rpy="0 0 0"/>
    <mass value="0.545696208866394"/>
    <inertia ixx="0.00016" iyy="0.000161" izz="0.00016" ixy="-0.0" iyz="0.0" ixz="-1e-06"/>
  </inertial>
  <visual>
    <origin xyz="0.215 -0.02 -0.2" rpy="0 0 0"/>
    <geometry>
      <mesh filename="file://$(find frame_description)/meshes/holder_4_1.stl" scale="0.001 0.001 0.001"/>
    </geometry>
    <material name="silver"/>
  </visual>
  <collision>
    <origin xyz="0.215 -0.02 -0.2" rpy="0 0 0"/>
    <geometry>
      <mesh filename="file://$(find frame_description)/meshes/holder_4_1.stl" scale="0.001 0.001 0.001"/>
    </geometry>
  </collision>
</link>

<link name="holder_3_1">
  <inertial>
    <origin xyz="0.01627435024563989 3.173676564605099e-10 0.0012743502456399047" rpy="0 0 0"/>
    <mass value="0.545696208866394"/>
    <inertia ixx="0.00016" iyy="0.000161" izz="0.00016" ixy="0.0" iyz="0.0" ixz="1e-06"/>
  </inertial>
  <visual>
    <origin xyz="0.215 -0.02 0.2" rpy="0 0 0"/>
    <geometry>
      <mesh filename="file://$(find frame_description)/meshes/holder_3_1.stl" scale="0.001 0.001 0.001"/>
    </geometry>
    <material name="silver"/>
  </visual>
  <collision>
    <origin xyz="0.215 -0.02 0.2" rpy="0 0 0"/>
    <geometry>
      <mesh filename="file://$(find frame_description)/meshes/holder_3_1.stl" scale="0.001 0.001 0.001"/>
    </geometry>
  </collision>
</link>

<link name="holder_3_1">
  <inertial>
    <origin xyz="0.0012743502456399047 3.173676564605099e-10 0.01627435024563989" rpy="0 0 0"/>
    <mass value="0.545696208866394"/>
    <inertia ixx="0.00016" iyy="0.000161" izz="0.00016" ixy="0.0" iyz="0.0" ixz="1e-06"/>
  </inertial>
  <visual>
    <origin xyz="0.2 -0.02 0.215" rpy="0 0 0"/>
    <geometry>
      <mesh filename="file://$(find frame_description)/meshes/holder_3_1.stl" scale="0.001 0.001 0.001"/>
    </geometry>
    <material name="silver"/>
  </visual>
  <collision>
    <origin xyz="0.2 -0.02 0.215" rpy="0 0 0"/>
    <geometry>
      <mesh filename="file://$(find frame_description)/meshes/holder_3_1.stl" scale="0.001 0.001 0.001"/>
    </geometry>
  </collision>
</link>

<link name="holder_2_1">
  <inertial>
    <origin xyz="-0.0012743502456399047 -1.9344432306001025e-11 0.01627435024563989" rpy="0 0 0"/>
    <mass value="0.545696208866394"/>
    <inertia ixx="0.00016" iyy="0.000161" izz="0.00016" ixy="0.0" iyz="-0.0" ixz="-1e-06"/>
  </inertial>
  <visual>
    <origin xyz="-0.2 -0.02 0.215" rpy="0 0 0"/>
    <geometry>
      <mesh filename="file://$(find frame_description)/meshes/holder_2_1.stl" scale="0.001 0.001 0.001"/>
    </geometry>
    <material name="silver"/>
  </visual>
  <collision>
    <origin xyz="-0.2 -0.02 0.215" rpy="0 0 0"/>
    <geometry>
      <mesh filename="file://$(find frame_description)/meshes/holder_2_1.stl" scale="0.001 0.001 0.001"/>
    </geometry>
  </collision>
</link>

<link name="holder_2_1">
  <inertial>
    <origin xyz="-0.01627435024563989 -1.9344432306001025e-11 0.0012743502456399047" rpy="0 0 0"/>
    <mass value="0.545696208866394"/>
    <inertia ixx="0.00016" iyy="0.000161" izz="0.00016" ixy="0.0" iyz="-0.0" ixz="-1e-06"/>
  </inertial>
  <visual>
    <origin xyz="-0.215 -0.02 0.2" rpy="0 0 0"/>
    <geometry>
      <mesh filename="file://$(find frame_description)/meshes/holder_2_1.stl" scale="0.001 0.001 0.001"/>
    </geometry>
    <material name="silver"/>
  </visual>
  <collision>
    <origin xyz="-0.215 -0.02 0.2" rpy="0 0 0"/>
    <geometry>
      <mesh filename="file://$(find frame_description)/meshes/holder_2_1.stl" scale="0.001 0.001 0.001"/>
    </geometry>
  </collision>
</link>

<link name="holder_1_1">
  <inertial>
    <origin xyz="-0.01627435024563989 -1.9344414958766265e-11 -0.0012743502456399047" rpy="0 0 0"/>
    <mass value="0.545696208866394"/>
    <inertia ixx="0.00016" iyy="0.000161" izz="0.00016" ixy="0.0" iyz="0.0" ixz="1e-06"/>
  </inertial>
  <visual>
    <origin xyz="-0.215 -0.02 -0.2" rpy="0 0 0"/>
    <geometry>
      <mesh filename="file://$(find frame_description)/meshes/holder_1_1.stl" scale="0.001 0.001 0.001"/>
    </geometry>
    <material name="silver"/>
  </visual>
  <collision>
    <origin xyz="-0.215 -0.02 -0.2" rpy="0 0 0"/>
    <geometry>
      <mesh filename="file://$(find frame_description)/meshes/holder_1_1.stl" scale="0.001 0.001 0.001"/>
    </geometry>
  </collision>
</link>

<link name="holder_1_1">
  <inertial>
    <origin xyz="-0.0012743502456399047 -1.9344414958766265e-11 -0.01627435024563989" rpy="0 0 0"/>
    <mass value="0.545696208866394"/>
    <inertia ixx="0.00016" iyy="0.000161" izz="0.00016" ixy="0.0" iyz="0.0" ixz="1e-06"/>
  </inertial>
  <visual>
    <origin xyz="-0.2 -0.02 -0.215" rpy="0 0 0"/>
    <geometry>
      <mesh filename="file://$(find frame_description)/meshes/holder_1_1.stl" scale="0.001 0.001 0.001"/>
    </geometry>
    <material name="silver"/>
  </visual>
  <collision>
    <origin xyz="-0.2 -0.02 -0.215" rpy="0 0 0"/>
    <geometry>
      <mesh filename="file://$(find frame_description)/meshes/holder_1_1.stl" scale="0.001 0.001 0.001"/>
    </geometry>
  </collision>
</link>

<link name="bldc_8_1">
  <inertial>
    <origin xyz="-9.850613495537841e-06 0.012072048037910045 2.6988692206020293e-05" rpy="0 0 0"/>
    <mass value="0.22635455509580407"/>
    <inertia ixx="6.6e-05" iyy="0.000112" izz="6.6e-05" ixy="0.0" iyz="-0.0" ixz="0.0"/>
  </inertial>
  <visual>
    <origin xyz="-0.2 -0.04 -0.2" rpy="0 0 0"/>
    <geometry>
      <mesh filename="file://$(find frame_description)/meshes/bldc_8_1.stl" scale="0.001 0.001 0.001"/>
    </geometry>
    <material name="silver"/>
  </visual>
  <collision>
    <origin xyz="-0.2 -0.04 -0.2" rpy="0 0 0"/>
    <geometry>
      <mesh filename="file://$(find frame_description)/meshes/bldc_8_1.stl" scale="0.001 0.001 0.001"/>
    </geometry>
  </collision>
</link>

<link name="bldc_7_1">
  <inertial>
    <origin xyz="2.6989159021245657e-05 0.012072048037909955 9.851740487398786e-06" rpy="0 0 0"/>
    <mass value="0.22635455509580502"/>
    <inertia ixx="6.6e-05" iyy="0.000112" izz="6.6e-05" ixy="-0.0" iyz="-0.0" ixz="-0.0"/>
  </inertial>
  <visual>
    <origin xyz="-0.2 -0.04 0.2" rpy="0 0 0"/>
    <geometry>
      <mesh filename="file://$(find frame_description)/meshes/bldc_7_1.stl" scale="0.001 0.001 0.001"/>
    </geometry>
    <material name="silver"/>
  </visual>
  <collision>
    <origin xyz="-0.2 -0.04 0.2" rpy="0 0 0"/>
    <geometry>
      <mesh filename="file://$(find frame_description)/meshes/bldc_7_1.stl" scale="0.001 0.001 0.001"/>
    </geometry>
  </collision>
</link>

<link name="bldc_6_1">
  <inertial>
    <origin xyz="2.6989159021273412e-05 0.012072048335933179 9.851740487398786e-06" rpy="0 0 0"/>
    <mass value="0.22635455509580502"/>
    <inertia ixx="6.6e-05" iyy="0.000112" izz="6.6e-05" ixy="-0.0" iyz="-0.0" ixz="-0.0"/>
  </inertial>
  <visual>
    <origin xyz="0.2 -0.04 0.2" rpy="0 0 0"/>
    <geometry>
      <mesh filename="file://$(find frame_description)/meshes/bldc_6_1.stl" scale="0.001 0.001 0.001"/>
    </geometry>
    <material name="silver"/>
  </visual>
  <collision>
    <origin xyz="0.2 -0.04 0.2" rpy="0 0 0"/>
    <geometry>
      <mesh filename="file://$(find frame_description)/meshes/bldc_6_1.stl" scale="0.001 0.001 0.001"/>
    </geometry>
  </collision>
</link>

<link name="bldc_5_1">
  <inertial>
    <origin xyz="-2.6989159019580322e-05 0.01207204803791747 -9.851740487953897e-06" rpy="0 0 0"/>
    <mass value="0.22635455509580502"/>
    <inertia ixx="6.6e-05" iyy="0.000112" izz="6.6e-05" ixy="0.0" iyz="0.0" ixz="-0.0"/>
  </inertial>
  <visual>
    <origin xyz="0.2 -0.04 -0.2" rpy="0 0 0"/>
    <geometry>
      <mesh filename="file://$(find frame_description)/meshes/bldc_5_1.stl" scale="0.001 0.001 0.001"/>
    </geometry>
    <material name="silver"/>
  </visual>
  <collision>
    <origin xyz="0.2 -0.04 -0.2" rpy="0 0 0"/>
    <geometry>
      <mesh filename="file://$(find frame_description)/meshes/bldc_5_1.stl" scale="0.001 0.001 0.001"/>
    </geometry>
  </collision>
</link>

<link name="bldc_4_1">
  <inertial>
    <origin xyz="-2.6989159021273412e-05 -0.012072048037909955 9.851740487398786e-06" rpy="0 0 0"/>
    <mass value="0.22635455509580502"/>
    <inertia ixx="6.6e-05" iyy="0.000112" izz="6.6e-05" ixy="-0.0" iyz="0.0" ixz="0.0"/>
  </inertial>
  <visual>
    <origin xyz="-0.2 -0.0 0.2" rpy="0 0 0"/>
    <geometry>
      <mesh filename="file://$(find frame_description)/meshes/bldc_4_1.stl" scale="0.001 0.001 0.001"/>
    </geometry>
    <material name="silver"/>
  </visual>
  <collision>
    <origin xyz="-0.2 -0.0 0.2" rpy="0 0 0"/>
    <geometry>
      <mesh filename="file://$(find frame_description)/meshes/bldc_4_1.stl" scale="0.001 0.001 0.001"/>
    </geometry>
  </collision>
</link>

<link name="bldc_3_1">
  <inertial>
    <origin xyz="-2.6989159021245657e-05 -0.01207204773988673 9.851740487398786e-06" rpy="0 0 0"/>
    <mass value="0.22635455509580502"/>
    <inertia ixx="6.6e-05" iyy="0.000112" izz="6.6e-05" ixy="-0.0" iyz="0.0" ixz="0.0"/>
  </inertial>
  <visual>
    <origin xyz="0.2 -0.0 0.2" rpy="0 0 0"/>
    <geometry>
      <mesh filename="file://$(find frame_description)/meshes/bldc_3_1.stl" scale="0.001 0.001 0.001"/>
    </geometry>
    <material name="silver"/>
  </visual>
  <collision>
    <origin xyz="0.2 -0.0 0.2" rpy="0 0 0"/>
    <geometry>
      <mesh filename="file://$(find frame_description)/meshes/bldc_3_1.stl" scale="0.001 0.001 0.001"/>
    </geometry>
  </collision>
</link>

<link name="bldc_2_1">
  <inertial>
    <origin xyz="2.6989159019635833e-05 -0.012072048037902619 -9.851740487953897e-06" rpy="0 0 0"/>
    <mass value="0.22635455509580502"/>
    <inertia ixx="6.6e-05" iyy="0.000112" izz="6.6e-05" ixy="0.0" iyz="-0.0" ixz="0.0"/>
  </inertial>
  <visual>
    <origin xyz="0.2 -0.0 -0.2" rpy="0 0 0"/>
    <geometry>
      <mesh filename="file://$(find frame_description)/meshes/bldc_2_1.stl" scale="0.001 0.001 0.001"/>
    </geometry>
    <material name="silver"/>
  </visual>
  <collision>
    <origin xyz="0.2 -0.0 -0.2" rpy="0 0 0"/>
    <geometry>
      <mesh filename="file://$(find frame_description)/meshes/bldc_2_1.stl" scale="0.001 0.001 0.001"/>
    </geometry>
  </collision>
</link>

<link name="bldc_1_1">
  <inertial>
    <origin xyz="-9.85174048737103e-06 -0.012072048037909984 -2.6989159021245657e-05" rpy="0 0 0"/>
    <mass value="0.22635455509580502"/>
    <inertia ixx="6.6e-05" iyy="0.000112" izz="6.6e-05" ixy="-0.0" iyz="-0.0" ixz="-0.0"/>
  </inertial>
  <visual>
    <origin xyz="-0.2 0.0 -0.2" rpy="0 0 0"/>
    <geometry>
      <mesh filename="file://$(find frame_description)/meshes/bldc_1_1.stl" scale="0.001 0.001 0.001"/>
    </geometry>
    <material name="silver"/>
  </visual>
  <collision>
    <origin xyz="-0.2 0.0 -0.2" rpy="0 0 0"/>
    <geometry>
      <mesh filename="file://$(find frame_description)/meshes/bldc_1_1.stl" scale="0.001 0.001 0.001"/>
    </geometry>
  </collision>
</link>

<link name="controller_1">
  <inertial>
    <origin xyz="0.029999999999999964 0.0075 -0.08999999999999991" rpy="0 0 0"/>
    <mass value="0.471"/>
    <inertia ixx="0.000107" iyy="0.000349" izz="0.00026" ixy="-0.0" iyz="-0.0" ixz="-0.0"/>
  </inertial>
  <visual>
    <origin xyz="0.0 -0.04 -0.15" rpy="0 0 0"/>
    <geometry>
      <mesh filename="file://$(find frame_description)/meshes/controller_1.stl" scale="0.001 0.001 0.001"/>
    </geometry>
    <material name="silver"/>
  </visual>
  <collision>
    <origin xyz="0.0 -0.04 -0.15" rpy="0 0 0"/>
    <geometry>
      <mesh filename="file://$(find frame_description)/meshes/controller_1.stl" scale="0.001 0.001 0.001"/>
    </geometry>
  </collision>
</link>

<link name="wifi_1">
  <inertial>
    <origin xyz="0.009999999999999766 0.008499999999999903 -0.13999999999999996" rpy="0 0 0"/>
    <mass value="0.0364905"/>
    <inertia ixx="7e-06" iyy="1.2e-05" izz="7e-06" ixy="-0.0" iyz="-0.0" ixz="0.0"/>
  </inertial>
  <visual>
    <origin xyz="0.055 -0.04 -0.2" rpy="0 0 0"/>
    <geometry>
      <mesh filename="file://$(find frame_description)/meshes/wifi_1.stl" scale="0.001 0.001 0.001"/>
    </geometry>
    <material name="silver"/>
  </visual>
  <collision>
    <origin xyz="0.055 -0.04 -0.2" rpy="0 0 0"/>
    <geometry>
      <mesh filename="file://$(find frame_description)/meshes/wifi_1.stl" scale="0.001 0.001 0.001"/>
    </geometry>
  </collision>
</link>

<link name="camera_1">
  <inertial>
    <origin xyz="-3.5527136788005004e-17 -0.015 -0.01999999999999999" rpy="0 0 0"/>
    <mass value="0.03975"/>
    <inertia ixx="5e-06" iyy="1e-05" izz="1.1e-05" ixy="0.0" iyz="0.0" ixz="0.0"/>
  </inertial>
  <visual>
    <origin xyz="0.0 -0.0 -0.15" rpy="0 0 0"/>
    <geometry>
      <mesh filename="file://$(find frame_description)/meshes/camera_1.stl" scale="0.001 0.001 0.001"/>
    </geometry>
    <material name="silver"/>
  </visual>
  <collision>
    <origin xyz="0.0 -0.0 -0.15" rpy="0 0 0"/>
    <geometry>
      <mesh filename="file://$(find frame_description)/meshes/camera_1.stl" scale="0.001 0.001 0.001"/>
    </geometry>
  </collision>
</link>

<link name="battery_1">
  <inertial>
    <origin xyz="0.0 0.032499999999999966 -0.06" rpy="0 0 0"/>
    <mass value="1.7679999999999996"/>
    <inertia ixx="0.00488" iyy="0.005201" izz="0.001565" ixy="0.0" iyz="-0.0" ixz="0.0"/>
  </inertial>
  <visual>
    <origin xyz="-0.0 -0.04 -0.0" rpy="0 0 0"/>
    <geometry>
      <mesh filename="file://$(find frame_description)/meshes/battery_1.stl" scale="0.001 0.001 0.001"/>
    </geometry>
    <material name="silver"/>
  </visual>
  <collision>
    <origin xyz="-0.0 -0.04 -0.0" rpy="0 0 0"/>
    <geometry>
      <mesh filename="file://$(find frame_description)/meshes/battery_1.stl" scale="0.001 0.001 0.001"/>
    </geometry>
  </collision>
</link>

<link name="prop_8_1">
  <inertial>
    <origin xyz="5.65554336695584e-09 0.0014016427242870277 -9.956738766803142e-10" rpy="0 0 0"/>
    <mass value="0.0335765475239113"/>
    <inertia ixx="1e-06" iyy="0.000111" izz="0.00011" ixy="0.0" iyz="-0.0" ixz="1e-06"/>
  </inertial>
  <visual>
    <origin xyz="-0.2 -0.066 -0.2" rpy="0 0 0"/>
    <geometry>
      <mesh filename="file://$(find frame_description)/meshes/prop_8_1.stl" scale="0.001 0.001 0.001"/>
    </geometry>
    <material name="silver"/>
  </visual>
  <collision>
    <origin xyz="-0.2 -0.066 -0.2" rpy="0 0 0"/>
    <geometry>
      <mesh filename="file://$(find frame_description)/meshes/prop_8_1.stl" scale="0.001 0.001 0.001"/>
    </geometry>
  </collision>
</link>

<link name="prop_7_1">
  <inertial>
    <origin xyz="9.956764301932708e-10 0.001401642724294494 5.655541951421483e-09" rpy="0 0 0"/>
    <mass value="0.0335765475239113"/>
    <inertia ixx="0.00011" iyy="0.000111" izz="1e-06" ixy="0.0" iyz="0.0" ixz="-1e-06"/>
  </inertial>
  <visual>
    <origin xyz="0.2 -0.066 -0.2" rpy="0 0 0"/>
    <geometry>
      <mesh filename="file://$(find frame_description)/meshes/prop_7_1.stl" scale="0.001 0.001 0.001"/>
    </geometry>
    <material name="silver"/>
  </visual>
  <collision>
    <origin xyz="0.2 -0.066 -0.2" rpy="0 0 0"/>
    <geometry>
      <mesh filename="file://$(find frame_description)/meshes/prop_7_1.stl" scale="0.001 0.001 0.001"/>
    </geometry>
  </collision>
</link>

<link name="prop_6_1">
  <inertial>
    <origin xyz="-9.956739044358898e-10 0.0014016430223102033 -5.65554336695584e-09" rpy="0 0 0"/>
    <mass value="0.0335765475239113"/>
    <inertia ixx="0.00011" iyy="0.000111" izz="1e-06" ixy="-0.0" iyz="-0.0" ixz="-1e-06"/>
  </inertial>
  <visual>
    <origin xyz="0.2 -0.066 0.2" rpy="0 0 0"/>
    <geometry>
      <mesh filename="file://$(find frame_description)/meshes/prop_6_1.stl" scale="0.001 0.001 0.001"/>
    </geometry>
    <material name="silver"/>
  </visual>
  <collision>
    <origin xyz="0.2 -0.066 0.2" rpy="0 0 0"/>
    <geometry>
      <mesh filename="file://$(find frame_description)/meshes/prop_6_1.stl" scale="0.001 0.001 0.001"/>
    </geometry>
  </collision>
</link>

<link name="prop_5_1">
  <inertial>
    <origin xyz="-9.956739321914654e-10 0.001401642724286986 -5.655543339200264e-09" rpy="0 0 0"/>
    <mass value="0.0335765475239113"/>
    <inertia ixx="0.00011" iyy="0.000111" izz="1e-06" ixy="-0.0" iyz="-0.0" ixz="-1e-06"/>
  </inertial>
  <visual>
    <origin xyz="-0.2 -0.066 0.2" rpy="0 0 0"/>
    <geometry>
      <mesh filename="file://$(find frame_description)/meshes/prop_5_1.stl" scale="0.001 0.001 0.001"/>
    </geometry>
    <material name="silver"/>
  </visual>
  <collision>
    <origin xyz="-0.2 -0.066 0.2" rpy="0 0 0"/>
    <geometry>
      <mesh filename="file://$(find frame_description)/meshes/prop_5_1.stl" scale="0.001 0.001 0.001"/>
    </geometry>
  </collision>
</link>

<link name="prop_4_1">
  <inertial>
    <origin xyz="9.956739044358898e-10 -0.0014016427242869722 -5.655543339200264e-09" rpy="0 0 0"/>
    <mass value="0.0335765475239113"/>
    <inertia ixx="0.00011" iyy="0.000111" izz="1e-06" ixy="-0.0" iyz="0.0" ixz="1e-06"/>
  </inertial>
  <visual>
    <origin xyz="-0.2 0.026 0.2" rpy="0 0 0"/>
    <geometry>
      <mesh filename="file://$(find frame_description)/meshes/prop_4_1.stl" scale="0.001 0.001 0.001"/>
    </geometry>
    <material name="silver"/>
  </visual>
  <collision>
    <origin xyz="-0.2 0.026 0.2" rpy="0 0 0"/>
    <geometry>
      <mesh filename="file://$(find frame_description)/meshes/prop_4_1.stl" scale="0.001 0.001 0.001"/>
    </geometry>
  </collision>
</link>

<link name="prop_3_1">
  <inertial>
    <origin xyz="5.65554336695584e-09 -0.0014016427242870139 9.956739321914654e-10" rpy="0 0 0"/>
    <mass value="0.0335765475239113"/>
    <inertia ixx="1e-06" iyy="0.000111" izz="0.00011" ixy="-0.0" iyz="-0.0" ixz="-1e-06"/>
  </inertial>
  <visual>
    <origin xyz="-0.2 0.026 -0.2" rpy="0 0 0"/>
    <geometry>
      <mesh filename="file://$(find frame_description)/meshes/prop_3_1.stl" scale="0.001 0.001 0.001"/>
    </geometry>
    <material name="silver"/>
  </visual>
  <collision>
    <origin xyz="-0.2 0.026 -0.2" rpy="0 0 0"/>
    <geometry>
      <mesh filename="file://$(find frame_description)/meshes/prop_3_1.stl" scale="0.001 0.001 0.001"/>
    </geometry>
  </collision>
</link>

<link name="prop_2_1">
  <inertial>
    <origin xyz="9.956739321914654e-10 -0.001401642426263755 -5.655543339200264e-09" rpy="0 0 0"/>
    <mass value="0.0335765475239113"/>
    <inertia ixx="0.00011" iyy="0.000111" izz="1e-06" ixy="-0.0" iyz="0.0" ixz="1e-06"/>
  </inertial>
  <visual>
    <origin xyz="0.2 0.026 0.2" rpy="0 0 0"/>
    <geometry>
      <mesh filename="file://$(find frame_description)/meshes/prop_2_1.stl" scale="0.001 0.001 0.001"/>
    </geometry>
    <material name="silver"/>
  </visual>
  <collision>
    <origin xyz="0.2 0.026 0.2" rpy="0 0 0"/>
    <geometry>
      <mesh filename="file://$(find frame_description)/meshes/prop_2_1.stl" scale="0.001 0.001 0.001"/>
    </geometry>
  </collision>
</link>

<link name="prop_1_1">
  <inertial>
    <origin xyz="-9.956764579488464e-10 -0.001401642724279662 5.655541840399181e-09" rpy="0 0 0"/>
    <mass value="0.0335765475239113"/>
    <inertia ixx="0.00011" iyy="0.000111" izz="1e-06" ixy="0.0" iyz="-0.0" ixz="1e-06"/>
  </inertial>
  <visual>
    <origin xyz="0.2 0.026 -0.2" rpy="0 0 0"/>
    <geometry>
      <mesh filename="file://$(find frame_description)/meshes/prop_1_1.stl" scale="0.001 0.001 0.001"/>
    </geometry>
    <material name="silver"/>
  </visual>
  <collision>
    <origin xyz="0.2 0.026 -0.2" rpy="0 0 0"/>
    <geometry>
      <mesh filename="file://$(find frame_description)/meshes/prop_1_1.stl" scale="0.001 0.001 0.001"/>
    </geometry>
  </collision>
</link>

<link name="gps_1">
  <inertial>
    <origin xyz="-1.1191130032256469e-06 0.12931717033763007 0.08998779941606269" rpy="0 0 0"/>
    <mass value="0.2057372858290306"/>
    <inertia ixx="0.000482" iyy="5e-05" izz="0.000482" ixy="0.0" iyz="0.0" ixz="0.0"/>
  </inertial>
  <visual>
    <origin xyz="0.055 -0.04 0.2" rpy="0 0 0"/>
    <geometry>
      <mesh filename="file://$(find frame_description)/meshes/gps_1.stl" scale="0.001 0.001 0.001"/>
    </geometry>
    <material name="silver"/>
  </visual>
  <collision>
    <origin xyz="0.055 -0.04 0.2" rpy="0 0 0"/>
    <geometry>
      <mesh filename="file://$(find frame_description)/meshes/gps_1.stl" scale="0.001 0.001 0.001"/>
    </geometry>
  </collision>
</link>

<link name="probe_1">
  <inertial>
    <origin xyz="0.0003461717210624382 1.5355466518769678e-06 0.12087134888980863" rpy="0 0 0"/>
    <mass value="0.873048184916524"/>
    <inertia ixx="0.004501" iyy="0.004517" izz="8e-05" ixy="-0.0" iyz="0.0" ixz="8e-06"/>
  </inertial>
  <visual>
    <origin xyz="0.0 -0.02 -0.15" rpy="0 0 0"/>
    <geometry>
      <mesh filename="file://$(find frame_description)/meshes/probe_1.stl" scale="0.001 0.001 0.001"/>
    </geometry>
    <material name="silver"/>
  </visual>
  <collision>
    <origin xyz="0.0 -0.02 -0.15" rpy="0 0 0"/>
    <geometry>
      <mesh filename="file://$(find frame_description)/meshes/probe_1.stl" scale="0.001 0.001 0.001"/>
    </geometry>
  </collision>
</link>

<joint name="Revolute 1" type="continuous">
  <origin xyz="-0.055 0.02 -0.2" rpy="0 0 0"/>
  <parent link="base_link"/>
  <child link="arm_7_1"/>
  <axis xyz="1.0 0.0 0.0"/>
</joint>

<joint name="Revolute 2" type="continuous">
  <origin xyz="-0.2 0.02 -0.055" rpy="0 0 0"/>
  <parent link="base_link"/>
  <child link="arm_8_1"/>
  <axis xyz="0.0 0.0 1.0"/>
</joint>

<joint name="Revolute 3" type="continuous">
  <origin xyz="0.2 0.02 0.055" rpy="0 0 0"/>
  <parent link="base_link"/>
  <child link="arm_6_1"/>
  <axis xyz="0.0 0.0 1.0"/>
</joint>

<joint name="Revolute 4" type="continuous">
  <origin xyz="0.055 0.02 0.2" rpy="0 0 0"/>
  <parent link="base_link"/>
  <child link="arm_5_1"/>
  <axis xyz="1.0 0.0 0.0"/>
</joint>

<joint name="Revolute 5" type="continuous">
  <origin xyz="0.2 0.02 -0.055" rpy="0 0 0"/>
  <parent link="base_link"/>
  <child link="arm_4_1"/>
  <axis xyz="0.0 0.0 1.0"/>
</joint>

<joint name="Revolute 6" type="continuous">
  <origin xyz="0.055 0.02 -0.2" rpy="0 0 0"/>
  <parent link="base_link"/>
  <child link="arm_3_1"/>
  <axis xyz="1.0 0.0 0.0"/>
</joint>

<joint name="Revolute 7" type="continuous">
  <origin xyz="-0.2 0.02 0.055" rpy="0 0 0"/>
  <parent link="base_link"/>
  <child link="arm_2_1"/>
  <axis xyz="0.0 0.0 1.0"/>
</joint>

<joint name="Revolute 8" type="continuous">
  <origin xyz="-0.055 0.02 0.2" rpy="0 0 0"/>
  <parent link="base_link"/>
  <child link="arm_1_1"/>
  <axis xyz="1.0 0.0 0.0"/>
</joint>

<joint name="Revolute 13" type="continuous">
  <origin xyz="-0.16 0.0 0.0" rpy="0 0 0"/>
  <parent link="arm_1_1"/>
  <child link="holder_4_1"/>
  <axis xyz="-0.0 0.0 -1.0"/>
</joint>

<joint name="Revolute 14" type="continuous">
  <origin xyz="-0.015 0.0 0.145" rpy="0 0 0"/>
  <parent link="arm_2_1"/>
  <child link="holder_4_1"/>
  <axis xyz="1.0 0.0 -0.0"/>
</joint>

<joint name="Revolute 15" type="continuous">
  <origin xyz="0.0 0.0 -0.16" rpy="0 0 0"/>
  <parent link="arm_8_1"/>
  <child link="holder_3_1"/>
  <axis xyz="1.0 0.0 0.0"/>
</joint>

<joint name="Revolute 16" type="continuous">
  <origin xyz="-0.145 0.0 -0.015" rpy="0 0 0"/>
  <parent link="arm_7_1"/>
  <child link="holder_3_1"/>
  <axis xyz="0.0 0.0 1.0"/>
</joint>

<joint name="Revolute 17" type="continuous">
  <origin xyz="0.16 0.0 0.0" rpy="0 0 0"/>
  <parent link="arm_3_1"/>
  <child link="holder_2_1"/>
  <axis xyz="0.0 0.0 1.0"/>
</joint>

<joint name="Revolute 18" type="continuous">
  <origin xyz="0.015 0.0 -0.145" rpy="0 0 0"/>
  <parent link="arm_4_1"/>
  <child link="holder_2_1"/>
  <axis xyz="-1.0 0.0 0.0"/>
</joint>

<joint name="Revolute 19" type="continuous">
  <origin xyz="0.0 0.0 0.16" rpy="0 0 0"/>
  <parent link="arm_6_1"/>
  <child link="holder_1_1"/>
  <axis xyz="-1.0 0.0 0.0"/>
</joint>

<joint name="Revolute 20" type="continuous">
  <origin xyz="0.145 0.0 0.015" rpy="0 0 0"/>
  <parent link="arm_5_1"/>
  <child link="holder_1_1"/>
  <axis xyz="0.0 0.0 -1.0"/>
</joint>

<joint name="Rigid 21" type="fixed">
  <origin xyz="0.0 0.02 -0.015" rpy="0 0 0"/>
  <parent link="holder_1_1"/>
  <child link="bldc_8_1"/>
</joint>

<joint name="Rigid 22" type="fixed">
  <origin xyz="-0.015 0.02 0.0" rpy="0 0 0"/>
  <parent link="holder_2_1"/>
  <child link="bldc_7_1"/>
</joint>

<joint name="Rigid 23" type="fixed">
  <origin xyz="0.0 0.02 0.015" rpy="0 0 0"/>
  <parent link="holder_3_1"/>
  <child link="bldc_6_1"/>
</joint>

<joint name="Rigid 24" type="fixed">
  <origin xyz="0.015 0.02 0.0" rpy="0 0 0"/>
  <parent link="holder_4_1"/>
  <child link="bldc_5_1"/>
</joint>

<joint name="Rigid 25" type="fixed">
  <origin xyz="-0.015 -0.02 0.0" rpy="0 0 0"/>
  <parent link="holder_2_1"/>
  <child link="bldc_4_1"/>
</joint>

<joint name="Rigid 26" type="fixed">
  <origin xyz="0.0 -0.02 0.015" rpy="0 0 0"/>
  <parent link="holder_3_1"/>
  <child link="bldc_3_1"/>
</joint>

<joint name="Rigid 27" type="fixed">
  <origin xyz="0.015 -0.02 0.0" rpy="0 0 0"/>
  <parent link="holder_4_1"/>
  <child link="bldc_2_1"/>
</joint>

<joint name="Rigid 28" type="fixed">
  <origin xyz="0.0 -0.02 -0.015" rpy="0 0 0"/>
  <parent link="holder_1_1"/>
  <child link="bldc_1_1"/>
</joint>

<joint name="Rigid 29" type="fixed">
  <origin xyz="0.0 0.04 0.15" rpy="0 0 0"/>
  <parent link="base_link"/>
  <child link="controller_1"/>
</joint>

<joint name="Rigid 30" type="fixed">
  <origin xyz="-0.055 0.04 0.2" rpy="0 0 0"/>
  <parent link="base_link"/>
  <child link="wifi_1"/>
</joint>

<joint name="Rigid 31" type="fixed">
  <origin xyz="0.0 0.0 0.15" rpy="0 0 0"/>
  <parent link="base_link"/>
  <child link="camera_1"/>
</joint>

<joint name="Rigid 32" type="fixed">
  <origin xyz="0.0 0.04 0.0" rpy="0 0 0"/>
  <parent link="base_link"/>
  <child link="battery_1"/>
</joint>

<joint name="Revolute 33" type="continuous">
  <origin xyz="0.0 0.026 0.0" rpy="0 0 0"/>
  <parent link="bldc_8_1"/>
  <child link="prop_8_1"/>
  <axis xyz="0.0 -1.0 0.0"/>
</joint>

<joint name="Revolute 34" type="continuous">
  <origin xyz="0.0 0.026 0.0" rpy="0 0 0"/>
  <parent link="bldc_5_1"/>
  <child link="prop_7_1"/>
  <axis xyz="-0.0 -1.0 0.0"/>
</joint>

<joint name="Revolute 35" type="continuous">
  <origin xyz="0.0 0.026 0.0" rpy="0 0 0"/>
  <parent link="bldc_6_1"/>
  <child link="prop_6_1"/>
  <axis xyz="0.0 -1.0 -0.0"/>
</joint>

<joint name="Revolute 36" type="continuous">
  <origin xyz="0.0 0.026 0.0" rpy="0 0 0"/>
  <parent link="bldc_7_1"/>
  <child link="prop_5_1"/>
  <axis xyz="0.0 -1.0 -0.0"/>
</joint>

<joint name="Revolute 37" type="continuous">
  <origin xyz="0.0 -0.026 0.0" rpy="0 0 0"/>
  <parent link="bldc_4_1"/>
  <child link="prop_4_1"/>
  <axis xyz="-0.0 1.0 -0.0"/>
</joint>

<joint name="Revolute 38" type="continuous">
  <origin xyz="0.0 -0.026 0.0" rpy="0 0 0"/>
  <parent link="bldc_1_1"/>
  <child link="prop_3_1"/>
  <axis xyz="0.0 1.0 -0.0"/>
</joint>

<joint name="Revolute 39" type="continuous">
  <origin xyz="0.0 -0.026 0.0" rpy="0 0 0"/>
  <parent link="bldc_3_1"/>
  <child link="prop_2_1"/>
  <axis xyz="-0.0 1.0 -0.0"/>
</joint>

<joint name="Revolute 40" type="continuous">
  <origin xyz="0.0 -0.026 0.0" rpy="0 0 0"/>
  <parent link="bldc_2_1"/>
  <child link="prop_1_1"/>
  <axis xyz="0.0 1.0 0.0"/>
</joint>

<joint name="Rigid 41" type="fixed">
  <origin xyz="-0.055 0.04 -0.2" rpy="0 0 0"/>
  <parent link="base_link"/>
  <child link="gps_1"/>
</joint>

<joint name="Rigid 42" type="fixed">
  <origin xyz="0.0 0.02 0.15" rpy="0 0 0"/>
  <parent link="base_link"/>
  <child link="probe_1"/>
</joint>

</robot>
