<sdf version="1.10">
  <world name="simple">
    <physics name="10ms" type="ode">
      <max_step_size>0.01</max_step_size>
      <real_time_factor>1</real_time_factor>
      <real_time_update_rate>1000</real_time_update_rate>
    </physics>
    <plugin name="ignition::gazebo::systems::Physics" filename="ignition-gazebo-physics-system"/>
    <plugin name="ignition::gazebo::systems::UserCommands" filename="ignition-gazebo-user-commands-system"/>
    <plugin name="ignition::gazebo::systems::SceneBroadcaster" filename="ignition-gazebo-scene-broadcaster-system"/>
    <plugin name="ignition::gazebo::systems::Sensors" filename="ignition-gazebo-sensors-system">
      <render_engine>ogre2</render_engine>
    </plugin>
    <gravity>0 0 -9.8000000000000007</gravity>
    <magnetic_field>5.5644999999999998e-06 2.2875799999999999e-05 -4.2388400000000002e-05</magnetic_field>
    <atmosphere type="adiabatic"/>
    <scene>
      <ambient>0.400000006 0.400000006 0.400000006 1</ambient>
      <background>0.699999988 0.699999988 0.699999988 1</background>
      <shadows>true</shadows>
    </scene>
    <model name="turret">
      <pose>0 0 0 0 0 0</pose>
      <joint name="base_link" type="fixed">
        <pose>0 0 0 0 0 0</pose>
        <parent>world</parent>
        <child>turret/base_link</child>
      </joint>
      <link name="turret/base_link">
        <pose>0 0 0 0 0 0</pose>
        <inertial>
          <pose>0 0 0 0 0 0</pose>
          <mass>0.10000000000000001</mass>
          <inertia>
            <ixx>0.10000000000000001</ixx>
            <ixy>0</ixy>
            <ixz>0</ixz>
            <iyy>0.10000000000000001</iyy>
            <iyz>0</iyz>
            <izz>0.10000000000000001</izz>
          </inertia>
        </inertial>
        <visual name="turret/base_link_visual">
          <pose>0 0 0.25 0 0 0</pose>
          <geometry>
            <cylinder>
              <length>0.5</length>
              <radius>0.025000000000000001</radius>
            </cylinder>
          </geometry>
          <material>
            <diffuse>1 1 1 1</diffuse>
            <ambient>1 1 1 1</ambient>
          </material>
        </visual>
        <enable_wind>false</enable_wind>
      </link>
      <joint name="joint1" type="revolute">
        <pose>0 0 0 0 0 0</pose>
        <parent>turret/base_link</parent>
        <child>turret/link1</child>
        <axis>
          <xyz>0 0 1</xyz>
          <limit>
            <lower>-3.1415999999999999</lower>
            <upper>3.1415999999999999</upper>
            <effort>10</effort>
            <velocity>3</velocity>
            <stiffness>100000000</stiffness>
            <dissipation>1</dissipation>
          </limit>
          <dynamics>
            <spring_reference>0</spring_reference>
            <spring_stiffness>0</spring_stiffness>
            <damping>0</damping>
            <friction>0</friction>
          </dynamics>
        </axis>
      </joint>
      <link name="turret/link1">
        <pose>0 0 0.5 0 0 0</pose>
        <inertial>
          <pose>0 0 0 0 0 0</pose>
          <mass>0.10000000000000001</mass>
          <inertia>
            <ixx>0.10000000000000001</ixx>
            <ixy>0</ixy>
            <ixz>0</ixz>
            <iyy>0.10000000000000001</iyy>
            <iyz>0</iyz>
            <izz>0.10000000000000001</izz>
          </inertia>
        </inertial>
        <visual name="turret/link1_visual">
          <pose>0 0 0 0 0 0</pose>
          <geometry>
            <sphere>
              <radius>0.02</radius>
            </sphere>
          </geometry>
          <material>
            <diffuse>0 0 0 1</diffuse>
            <ambient>0 0 0 1</ambient>
          </material>
        </visual>
        <enable_wind>false</enable_wind>
      </link>
      <joint name="joint2" type="revolute">
        <pose>0 0 -2.7755575615628914e-17 0 0 0</pose>
        <parent>turret/link1</parent>
        <child>turret/link2</child>
        <axis>
          <xyz>0 0 1</xyz>
          <limit>
            <lower>-1.2</lower>
            <upper>1.2</upper>
            <effort>10</effort>
            <velocity>3</velocity>
            <stiffness>100000000</stiffness>
            <dissipation>1</dissipation>
          </limit>
          <dynamics>
            <spring_reference>0</spring_reference>
            <spring_stiffness>0</spring_stiffness>
            <damping>0</damping>
            <friction>0</friction>
          </dynamics>
        </axis>
      </joint>
      <link name="turret/link2">
        <pose>0 0 0.5 1.57079632679 0 0</pose>
        <inertial>
          <pose>0 0 0 0 0 0</pose>
          <mass>0.20000000000000001</mass>
          <inertia>
            <ixx>0.20000000000000001</ixx>
            <ixy>0</ixy>
            <ixz>0</ixz>
            <iyy>0.20000000000000001</iyy>
            <iyz>0</iyz>
            <izz>0.20000000000000001</izz>
          </inertia>
        </inertial>
        <visual name="turret/link2_visual">
          <pose>0 0 0 0 1.5707963267948966 0</pose>
          <geometry>
            <cylinder>
              <length>0.01</length>
              <radius>0.021000000000000001</radius>
            </cylinder>
          </geometry>
          <material>
            <diffuse>1 0 0 1</diffuse>
            <ambient>1 0 0 1</ambient>
          </material>
        </visual>
        <visual name="turret/link2_2_visual_1">
          <pose>0 0.029999999999999999 0 1.57079632679 0 0</pose>
          <geometry>
            <cylinder>
              <length>0.059999999999999998</length>
              <radius>0.0040000000000000001</radius>
            </cylinder>
          </geometry>
          <material>
            <diffuse>1 0 0 1</diffuse>
            <ambient>1 0 0 1</ambient>
          </material>
        </visual>
        <enable_wind>false</enable_wind>
      </link>
      <joint name="joint3" type="prismatic">
        <pose>0 0 0 0 0 0</pose>
        <parent>turret/link2</parent>
        <child>turret/link3</child>
        <axis>
          <xyz>0 0 1</xyz>
          <limit>
            <lower>0</lower>
            <upper>0.040000000000000001</upper>
            <effort>10</effort>
            <velocity>3</velocity>
            <stiffness>100000000</stiffness>
            <dissipation>1</dissipation>
          </limit>
          <dynamics>
            <spring_reference>0</spring_reference>
            <spring_stiffness>0</spring_stiffness>
            <damping>0</damping>
            <friction>0</friction>
          </dynamics>
        </axis>
      </joint>
      <link name="turret/link3">
        <pose>0 0 0.49999999999902001 0 0 0</pose>
        <inertial>
          <pose>0 0 0.05000000000000001 0 0 0</pose>
          <mass>0.20000000000000001</mass>
          <inertia>
            <ixx>0.20050000000000001</ixx>
            <ixy>0</ixy>
            <ixz>0</ixz>
            <iyy>0.20050000000000001</iyy>
            <iyz>0</iyz>
            <izz>0.20000000000000001</izz>
          </inertia>
        </inertial>
        <visual name="turret/link3_visual">
          <pose>0 0 0.059999999999999998 0 0 0</pose>
          <geometry>
            <cylinder>
              <length>0.080000000000000002</length>
              <radius>0.0035000000000000001</radius>
            </cylinder>
          </geometry>
          <material>
            <diffuse>1 1 1 1</diffuse>
            <ambient>1 1 1 1</ambient>
          </material>
        </visual>
        <visual name="turret/link3_fixed_joint_lump__turret/tool0_visual_1">
          <pose>2.1684043449710089e-19 -0.001 0.10000000000000001 1.5707963267948972 1.5707963057214724 0</pose>
          <geometry>
            <sphere>
              <radius>0.0040000000000000001</radius>
            </sphere>
          </geometry>
          <material>
            <diffuse>0 1 0 1</diffuse>
            <ambient>0 1 0 1</ambient>
          </material>
        </visual>
        <sensor name="camera" type="camera">
          <pose>0 0 0.10000000000000001 -3.1415926535293441 1.5707926536057681 1.5707926536359922</pose>
          <topic>turret/image</topic>
          <update_rate>30</update_rate>
          <enable_metrics>false</enable_metrics>
          <camera name="__default__">
            <pose>0 0 0 0 0 0</pose>
            <horizontal_fov>1.0469999999999999</horizontal_fov>
            <image>
              <width>640</width>
              <height>400</height>
              <format>RGB_INT8</format>
              <anti_aliasing>4</anti_aliasing>
            </image>
            <camera_info_topic>__default__</camera_info_topic>
            <trigger_topic></trigger_topic>
            <triggered>false</triggered>
            <clip>
              <near>0.050000000000000003</near>
              <far>100</far>
            </clip>
            <save enabled="false">
              <path>__default__</path>
            </save>
            <visibility_mask>4294967295</visibility_mask>
            <noise>
              <type>none</type>
              <mean>0</mean>
              <stddev>0</stddev>
            </noise>
            <distortion>
              <k1>0</k1>
              <k2>0</k2>
              <k3>0</k3>
              <p1>0</p1>
              <p2>0</p2>
              <center>0.5 0.5</center>
            </distortion>
            <lens>
              <type>stereographic</type>
              <scale_to_hfov>true</scale_to_hfov>
              <cutoff_angle>1.5707963267948966</cutoff_angle>
              <env_texture_size>256</env_texture_size>
            </lens>
            <optical_frame_id>turret/tool0</optical_frame_id>
          </camera>
        </sensor>
        <enable_wind>false</enable_wind>
      </link>
      <plugin name="ignition::gazebo::systems::JointController" filename="libignition-gazebo-joint-controller-system.so">
        <joint_name>joint1</joint_name>
        <topic>turret/joint1_cmd_vel</topic>
      </plugin>
      <plugin name="ignition::gazebo::systems::JointController" filename="libignition-gazebo-joint-controller-system.so">
        <joint_name>joint2</joint_name>
        <topic>turret/joint2_cmd_vel</topic>
      </plugin>
      <plugin name="ignition::gazebo::systems::JointController" filename="libignition-gazebo-joint-controller-system.so">
        <joint_name>joint3</joint_name>
        <topic>turret/joint3_cmd_vel</topic>
      </plugin>
      <plugin name="ignition::gazebo::systems::JointStatePublisher" filename="ignition-gazebo-joint-state-publisher-system"/>
      <frame name="link2_2" attached_to="turret/link2">
        <pose>0 0 0 0 0 0</pose>
      </frame>
      <frame name="turret/link2_2" attached_to="link2_2">
        <pose>0 0 0 0 0 0</pose>
      </frame>
      <frame name="link4_2" attached_to="turret/link3">
        <pose>0 0 0.10000000000000001 1.5707963267948957 1.5707963267948966 0</pose>
      </frame>
      <frame name="turret/tool0" attached_to="link4_2">
        <pose>0 0 0 0 0 0</pose>
      </frame>
      <static>false</static>
      <self_collide>false</self_collide>
    </model>
    <light name="sun" type="directional">
      <pose>0 0 10 0 0 0</pose>
      <cast_shadows>true</cast_shadows>
      <intensity>1</intensity>
      <direction>-0.5 0.10000000000000001 -0.90000000000000002</direction>
      <diffuse>1 1 1 1</diffuse>
      <specular>0.5 0.5 0.5 1</specular>
      <attenuation>
        <range>1000</range>
        <linear>0.01</linear>
        <constant>0.90000000000000002</constant>
        <quadratic>0.001</quadratic>
      </attenuation>
      <spot>
        <inner_angle>0</inner_angle>
        <outer_angle>0</outer_angle>
        <falloff>0</falloff>
      </spot>
    </light>
  </world>
</sdf>